<?xml version="1.0"?>
<robot xmlns:xacro="http://www.ros.org/wiki/xacro">

  <!-- ======================= -->
  <!-- WHEEL MACRO             -->
  <!-- ======================= -->

  <xacro:macro name="wheel" params="prefix parent x_pos y_pos">
    
    <!-- Wheel Link -->
    <link name="${prefix}_wheel_link">
      <visual>
        <origin xyz="0 0 0" rpy="${pi/2} 0 0"/>
        <geometry>
          <cylinder radius="${wheel_radius}" length="${wheel_width}"/>
        </geometry>
        <material name="dark_gray"/>
      </visual>
      
      <collision>
        <origin xyz="0 0 0" rpy="${pi/2} 0 0"/>
        <geometry>
          <cylinder radius="${wheel_radius}" length="${wheel_width}"/>
        </geometry>
      </collision>
      
      <xacro:wheel_inertia m="${wheel_mass}" r="${wheel_radius}" h="${wheel_width}"/>
    </link>

    <!-- Wheel Joint -->
    <joint name="${prefix}_wheel_joint" type="continuous">
      <parent link="${parent}"/>
      <child link="${prefix}_wheel_link"/>
      <origin xyz="${x_pos} ${y_pos} 0" rpy="0 0 0"/>
      <axis xyz="0 1 0"/>
      <dynamics damping="0.1" friction="0.1"/>
      <limit effort="${max_wheel_torque}" velocity="20.0"/>
    </joint>

    <!-- Gazebo wheel properties -->
    <gazebo reference="${prefix}_wheel_link">
      <material>Gazebo/DarkGrey</material>
      <mu1>${wheel_friction_mu1}</mu1>
      <mu2>${wheel_friction_mu2}</mu2>
      <kp>${wheel_kp}</kp>
      <kd>${wheel_kd}</kd>
      <minDepth>0.001</minDepth>
      <maxVel>1.0</maxVel>
      <fdir1>1 0 0</fdir1>
    </gazebo>

    <!-- Transmission for ros2_control -->
    <transmission name="${prefix}_wheel_transmission">
      <type>transmission_interface/SimpleTransmission</type>
      <joint name="${prefix}_wheel_joint">
        <hardwareInterface>hardware_interface/VelocityJointInterface</hardwareInterface>
      </joint>
      <actuator name="${prefix}_wheel_motor">
        <hardwareInterface>hardware_interface/VelocityJointInterface</hardwareInterface>
        <mechanicalReduction>1</mechanicalReduction>
      </actuator>
    </transmission>

  </xacro:macro>

</robot>
